# Author: Malgor
# From: Minecraft Forums

weight=10
embed_into_distance=11
dimensions=16,10,10
max_leveling=2


rule1=1,90,ttfcapi:fakeigincobble-1,terrafirmacraft:StoneIgInBrick-1,terrafirmacraft:StoneIgInBrick-1
rule2=1,90,customitems:diorite_smooth_stone_slab
rule3=0,100,PRESERVE
rule4=1,100,terrafirmacraft:Chest TFC-0-EASY,terrafirmacraft:Chest TFC-0-EASY,terrafirmacraft:Chest TFC-0-MEDIUM,terrafirmacraft:Chest TFC-0-MEDIUM,terrafirmacraft:Chest TFC-0-HARD,0,0,0,0
rule5=0,75,minecraft:tnt
rule6=0,100,0,minecraft:stone_pressure_plate
rule7=0,100,ttfcapi:fakeigincobble-1,terrafirmacraft:StoneIgInBrick-1,terrafirmacraft:StoneIgInBrick-1
rule8=0,100,terrafirmacraft:StoneIgInBrick-1
rule9=2,80,customitems:diorite_smooth_stone_slab
rule10=2,75,terrafirmacraft:Torch-1
rule11=2,75,terrafirmacraft:Torch-2
rule12=2,75,terrafirmacraft:Torch-4
rule13=2,75,terrafirmacraft:Torch-3
rule14=0,100,minecraft:stone_pressure_plate
rule15=0,100,ttfcapi:fakeigincobble-1,terrafirmacraft:StoneIgInBrick-1

layer
3,3,3,3,3,3,3,3,3,3
3,3,3,3,3,3,3,3,3,3
3,3,5,5,5,5,5,5,3,3
3,3,5,5,5,5,5,5,3,3
3,3,5,5,5,5,5,5,3,3
3,3,5,5,5,5,5,5,3,3
3,3,5,5,5,5,5,5,3,3
3,3,5,5,5,5,5,5,3,3
3,3,3,3,3,3,3,3,3,3
3,3,3,3,3,3,3,3,3,3
endlayer

layer
3,3,3,3,3,3,3,3,3,3
3,3,3,3,3,3,3,3,3,3
3,3,7,7,7,7,7,7,3,3
3,3,7,7,15,15,15,7,3,3
3,3,7,15,15,15,15,7,3,3
3,3,7,15,15,15,15,7,3,3
3,3,7,15,15,15,15,7,3,3
3,3,7,7,7,7,7,7,3,3
3,3,3,3,3,3,3,3,3,3
3,3,3,3,3,3,3,3,3,3
endlayer

layer
3,3,3,3,3,3,3,3,3,3
3,3,3,3,3,3,3,3,3,3
3,3,7,7,7,7,7,7,3,3
3,3,7,4,6,6,6,7,3,3
3,3,7,6,6,6,6,7,3,3
3,3,7,6,6,6,6,7,3,3
3,3,7,6,6,6,6,7,3,3
3,3,7,7,7,7,7,7,3,3
3,3,3,3,3,3,3,3,3,3
3,3,3,3,3,3,3,3,3,3
endlayer

layer
3,3,3,3,3,3,3,3,3,3
3,3,3,3,3,3,3,3,3,3
3,3,7,7,7,7,7,7,3,3
3,3,7,10,10,10,10,7,3,3
3,3,7,0,0,0,0,7,3,3
3,3,7,0,0,0,0,7,3,3
3,3,7,0,0,0,0,7,3,3
3,3,7,7,7,7,7,7,3,3
3,3,3,3,3,3,3,3,3,3
3,3,3,3,3,3,3,3,3,3
endlayer

layer
3,3,3,3,3,3,3,3,3,3
3,3,3,3,3,3,3,3,3,3
3,3,7,7,7,7,7,7,3,3
3,3,7,0,0,0,0,7,3,3
3,3,7,0,0,0,0,7,3,3
3,3,7,0,0,0,0,7,3,3
3,3,7,0,0,0,0,7,3,3
3,3,7,7,7,7,7,7,3,3
3,3,3,3,3,3,3,3,3,3
3,3,3,3,3,3,3,3,3,3
endlayer

layer
3,3,3,3,3,3,3,3,3,3
3,3,3,3,3,3,3,3,3,3
3,3,7,7,7,7,7,7,3,3
3,3,7,8,8,8,8,7,3,3
3,3,7,8,8,8,8,7,3,3
3,3,7,8,8,8,8,7,3,3
3,3,7,8,8,8,0,7,3,3
3,3,7,7,7,7,7,7,3,3
3,3,3,3,3,3,3,3,3,3
3,3,3,3,3,3,3,3,3,3
endlayer

layer
3,3,3,3,3,3,3,3,3,3
3,3,3,3,3,3,3,3,3,3
3,3,7,7,7,7,7,7,3,3
3,3,7,8,8,8,8,7,3,3
3,3,7,8,8,8,8,7,3,3
3,3,7,8,8,8,8,7,3,3
3,3,7,8,8,8,0,7,3,3
3,3,7,7,7,7,7,7,3,3
3,3,3,3,3,3,3,3,3,3
3,3,3,3,3,3,3,3,3,3
endlayer

layer
3,3,3,3,3,3,3,3,3,3
3,3,3,3,3,3,3,3,3,3
3,3,3,3,3,3,3,3,3,3
3,3,3,8,8,8,8,3,3,3
3,3,3,8,8,8,8,3,3,3
3,3,3,8,8,8,8,3,3,3
3,3,3,8,8,8,8,3,3,3
3,3,3,3,3,3,3,3,3,3
3,3,3,3,3,3,3,3,3,3
3,3,3,3,3,3,3,3,3,3
endlayer

layer
1,1,1,1,1,1,1,1,1,1
1,1,1,1,1,1,1,1,1,1
1,1,1,1,1,1,1,1,1,1
1,1,1,1,1,1,1,1,1,1
1,1,1,1,1,1,1,1,1,1
1,1,1,1,1,1,1,1,1,1
1,1,1,1,1,1,8,1,1,1
1,1,1,1,1,1,1,1,1,1
1,1,1,1,1,1,1,1,1,1
1,1,1,1,1,1,1,1,1,1
endlayer

layer
3,3,3,3,3,3,3,3,3,3
3,1,1,1,1,1,1,1,1,3
3,1,1,1,1,1,1,1,1,3
3,1,1,1,1,1,1,1,1,3
3,1,1,1,1,1,1,1,1,3
3,1,1,1,1,1,1,1,1,3
3,1,1,1,1,1,1,1,1,3
3,1,1,1,1,1,1,1,1,3
3,1,1,1,1,1,1,1,1,3
3,3,3,3,3,3,3,3,3,3
endlayer

layer
3,3,3,3,3,3,3,3,3,3
3,3,3,3,3,3,3,3,3,3
3,3,1,1,1,1,1,1,3,3
3,3,1,1,1,1,1,1,3,3
3,3,1,1,1,1,1,1,3,3
3,3,1,1,1,1,1,1,3,3
3,3,1,1,1,1,1,1,3,3
3,3,1,1,1,1,1,1,3,3
3,3,3,3,3,3,3,3,3,3
3,3,3,3,3,3,3,3,3,3
endlayer

layer
3,3,3,3,3,3,3,3,3,3
3,3,3,3,3,3,3,3,3,3
3,3,3,3,3,3,3,3,3,3
3,3,3,1,1,1,1,3,3,3
3,3,3,1,1,1,1,3,3,3
3,3,3,1,1,1,1,3,3,3
3,3,3,1,1,1,1,3,3,3
3,3,3,3,3,3,3,3,3,3
3,3,3,3,3,3,3,3,3,3
3,3,3,3,3,3,3,3,3,3
endlayer

layer
3,3,3,3,3,3,3,3,3,3
3,3,3,3,3,3,3,3,3,3
3,3,3,3,3,3,3,3,3,3
3,3,3,1,0,0,1,3,3,3
3,3,3,0,0,0,0,3,3,3
3,3,3,0,0,0,0,3,3,3
3,3,3,1,0,0,1,3,3,3
3,3,3,3,3,3,3,3,3,3
3,3,3,3,3,3,3,3,3,3
3,3,3,3,3,3,3,3,3,3
endlayer

layer
3,3,3,3,3,3,3,3,3,3
3,3,3,3,3,3,3,3,3,3
3,3,3,3,3,3,3,3,3,3
3,3,3,1,0,0,1,3,3,3
3,3,3,0,0,0,0,3,3,3
3,3,3,0,0,0,0,3,3,3
3,3,3,1,0,0,1,3,3,3
3,3,3,3,3,3,3,3,3,3
3,3,3,3,3,3,3,3,3,3
3,3,3,3,3,3,3,3,3,3
endlayer

layer
3,3,3,3,3,3,3,3,3,3
3,3,3,3,3,3,3,3,3,3
3,3,3,11,3,3,11,3,3,3
3,3,13,1,0,0,1,ttfcapi:fakeigincobble-1,3,3
3,3,3,0,0,0,0,3,3,3
3,3,3,0,0,0,0,3,3,3
3,3,13,1,0,0,1,ttfcapi:fakeigincobble-1,3,3
3,3,3,10,3,3,10,3,3,3
3,3,3,3,3,3,3,3,3,3
3,3,3,3,3,3,3,3,3,3
endlayer

layer
3,3,3,3,3,3,3,3,3,3
3,3,3,3,3,3,3,3,3,3
3,3,3,3,3,3,3,3,3,3
3,3,3,9,9,9,9,3,3,3
3,3,3,9,3,3,9,3,3,3
3,3,3,9,3,3,9,3,3,3
3,3,3,9,9,9,9,3,3,3
3,3,3,3,3,3,3,3,3,3
3,3,3,3,3,3,3,3,3,3
3,3,3,3,3,3,3,3,3,3
endlayer