# Converted from schematic
# THIS TEMPLATE USES DEFAULTS!  Please edit for corrections.
# If you need help, consult template_rules.txt
biomesToSpawnIn=High Hills,High Hills Edge,High Plains,Plains,Rolling Hills
weight=2
embed_into_distance=2
unacceptable_target_blocks=flowing_water,water,flowing_lava,lava,terrafirmacraft:SaltWaterStationary,terrafirmacraft:FreshWaterStationary
dimensions=9,9,8
allowable_overhang=1
max_cut_in=2
cut_in_buffer=1
max_leveling=2
leveling_buffer=1
preserve_water=1
preserve_lava=1
preserve_plants=1


rule1=0,100,preserveBlock
rule2=0,100,preserveBlock
rule3=0,100,terrafirmacraft:StoneIgInBrick-1
rule4=0,100,ttfcapi:mossigincobble-1
rule5=0,100,customitems:andesite_cobblestone_stairs-2
rule6=0,100,customitems:andesite_cobblestone_stairs-3
rule7=0,100,customitems:andesite_cobblestone_stairs-0
rule8=0,100,customitems:andesite_cobblestone_stairs-1
rule9=0,100,terrafirmacraft:StoneIgExBrick-3
rule10=0,100,terrafirmacraft:planks-1


layer
1,1,1,1,1,1,1,1
1,1,1,1,1,1,1,1
1,1,1,1,1,1,1,1
1,1,1,1,1,1,1,1
1,1,1,1,1,1,1,1
1,1,1,1,1,1,1,1
1,1,1,1,1,1,1,1
1,1,1,1,1,1,1,1
1,1,1,1,1,1,1,1
endlayer

layer
2,2,2,1,1,2,2,2
2,2,1,1,1,1,2,2
2,1,1,3,3,1,1,2
1,1,3,3,4,3,1,1
2,1,3,3,3,3,1,1
1,1,3,3,4,3,1,1
2,1,1,3,3,1,1,2
2,2,1,1,1,1,2,2
2,2,2,1,1,2,2,2
endlayer

layer
0,0,0,0,7,0,0,0
0,0,6,0,3,0,0,0
0,6,3,4,0,0,5,0
6,3,5,0,0,0,3,5
0,0,0,0,0,6,3,5
6,3,5,0,0,0,3,0
0,0,3,4,0,0,0,0
0,0,6,3,3,5,0,0
0,0,0,0,8,0,0,0
endlayer

layer
0,0,0,0,0,0,0,0
0,0,0,0,3,0,0,0
0,0,3,0,0,0,0,0
0,3,0,0,0,0,3,0
0,0,0,0,0,0,0,0
0,3,0,0,0,0,3,0
0,0,9,0,0,3,0,0
0,0,0,0,3,0,0,0
0,0,0,0,0,0,0,0
endlayer

layer
0,0,0,0,0,0,0,0
0,0,0,0,0,0,0,0
0,0,3,0,0,0,0,0
0,3,0,0,0,0,3,0
0,0,0,0,0,0,0,0
0,0,0,0,0,0,3,0
0,0,9,0,0,3,0,0
0,0,0,0,0,0,0,0
0,0,0,0,0,0,0,0
endlayer

layer
0,0,0,0,0,0,0,0
0,0,0,0,0,0,0,0
0,0,0,0,0,0,0,0
0,0,0,0,0,0,3,0
0,0,0,0,0,0,3,0
0,0,0,0,0,0,3,0
0,0,3,0,0,3,0,0
0,0,0,3,3,0,0,0
0,0,0,0,0,0,0,0
endlayer

layer
0,0,0,0,0,0,0,0
0,0,0,0,0,0,0,0
0,0,0,0,0,0,0,0
0,0,0,0,0,0,3,0
0,0,0,0,0,0,3,0
0,0,0,0,0,0,3,0
0,0,0,0,0,3,0,0
0,0,0,3,3,0,0,0
0,0,0,0,0,0,0,0
endlayer

layer
0,0,0,0,0,0,0,0
0,0,0,0,0,0,0,0
0,0,0,0,0,0,10,0
0,0,0,0,0,0,10,10
0,0,0,0,0,0,10,10
0,0,0,0,0,0,10,10
0,0,0,0,0,0,10,0
0,0,0,0,10,10,0,0
0,0,0,10,10,0,0,0
endlayer

layer
0,0,0,0,0,0,0,0
0,0,0,0,0,0,0,0
0,0,0,0,0,0,0,0
0,0,0,0,0,0,0,0
0,0,0,0,0,0,10,0
0,0,0,0,0,0,10,0
0,0,0,0,0,0,0,0
0,0,0,0,0,0,0,0
0,0,0,0,0,0,0,0
endlayer

